ERROR 2021-12-21 10:44:53,884 log 228 Internal Server Error: /users/register
Traceback (most recent call last):
  File "D:\(Project\Envs\MyDjango-UsDAF7iD\lib\site-packages\django\core\handlers\exception.py", line 34, in inner
    response = get_response(request)
  File "D:\(Project\Envs\MyDjango-UsDAF7iD\lib\site-packages\django\core\handlers\base.py", line 126, in _get_response
    "returned None instead." % (callback.__module__, view_name)
ValueError: The view apps.users.views.RegisterView didn't return an HttpResponse object. It returned None instead.
ERROR 2021-12-21 10:45:45,410 log 228 Internal Server Error: /users/register
Traceback (most recent call last):
  File "D:\(Project\Envs\MyDjango-UsDAF7iD\lib\site-packages\django\core\handlers\exception.py", line 34, in inner
    response = get_response(request)
  File "D:\(Project\Envs\MyDjango-UsDAF7iD\lib\site-packages\django\core\handlers\base.py", line 126, in _get_response
    "returned None instead." % (callback.__module__, view_name)
ValueError: The view apps.users.views.RegisterView didn't return an HttpResponse object. It returned None instead.
ERROR 2021-12-21 11:40:19,636 log 228 Internal Server Error: /users/register
Traceback (most recent call last):
  File "D:\(Project\Envs\MyDjango-UsDAF7iD\lib\site-packages\django\core\handlers\exception.py", line 34, in inner
    response = get_response(request)
  File "D:\(Project\Envs\MyDjango-UsDAF7iD\lib\site-packages\django\core\handlers\base.py", line 126, in _get_response
    "returned None instead." % (callback.__module__, view_name)
ValueError: The view apps.users.views.RegisterView didn't return an HttpResponse object. It returned None instead.
ERROR 2021-12-21 11:40:30,142 log 228 Internal Server Error: /users/register
Traceback (most recent call last):
  File "D:\(Project\Envs\MyDjango-UsDAF7iD\lib\site-packages\django\core\handlers\exception.py", line 34, in inner
    response = get_response(request)
  File "D:\(Project\Envs\MyDjango-UsDAF7iD\lib\site-packages\django\core\handlers\base.py", line 126, in _get_response
    "returned None instead." % (callback.__module__, view_name)
ValueError: The view apps.users.views.RegisterView didn't return an HttpResponse object. It returned None instead.
ERROR 2021-12-21 15:04:07,376 log 228 Internal Server Error: /users/register
Traceback (most recent call last):
  File "D:\(Project\Envs\MyDjango-UsDAF7iD\lib\site-packages\django\core\handlers\exception.py", line 34, in inner
    response = get_response(request)
  File "D:\(Project\Envs\MyDjango-UsDAF7iD\lib\site-packages\django\core\handlers\base.py", line 115, in _get_response
    response = self.process_exception_by_middleware(e, request)
  File "D:\(Project\Envs\MyDjango-UsDAF7iD\lib\site-packages\django\core\handlers\base.py", line 113, in _get_response
    response = wrapped_callback(request, *callback_args, **callback_kwargs)
  File "D:\(Project\Envs\MyDjango-UsDAF7iD\lib\site-packages\django\views\generic\base.py", line 71, in view
    return self.dispatch(request, *args, **kwargs)
  File "D:\(Project\Envs\MyDjango-UsDAF7iD\lib\site-packages\django\views\generic\base.py", line 97, in dispatch
    return handler(request, *args, **kwargs)
  File "D:\(Project\MyDjango\ltmall\apps\users\views.py", line 34, in post
    res = (i for i in info.values() for info in user_info)
NameError: name 'info' is not defined
ERROR 2021-12-21 15:06:36,660 log 228 Internal Server Error: /users/register
Traceback (most recent call last):
  File "D:\(Project\Envs\MyDjango-UsDAF7iD\lib\site-packages\django\core\handlers\exception.py", line 34, in inner
    response = get_response(request)
  File "D:\(Project\Envs\MyDjango-UsDAF7iD\lib\site-packages\django\core\handlers\base.py", line 115, in _get_response
    response = self.process_exception_by_middleware(e, request)
  File "D:\(Project\Envs\MyDjango-UsDAF7iD\lib\site-packages\django\core\handlers\base.py", line 113, in _get_response
    response = wrapped_callback(request, *callback_args, **callback_kwargs)
  File "D:\(Project\Envs\MyDjango-UsDAF7iD\lib\site-packages\django\views\generic\base.py", line 71, in view
    return self.dispatch(request, *args, **kwargs)
  File "D:\(Project\Envs\MyDjango-UsDAF7iD\lib\site-packages\django\views\generic\base.py", line 97, in dispatch
    return handler(request, *args, **kwargs)
  File "D:\(Project\MyDjango\ltmall\apps\users\views.py", line 34, in post
    res = [i for i in info.values() for info in user_info]
NameError: name 'info' is not defined
ERROR 2021-12-21 15:08:51,845 log 228 Internal Server Error: /users/register
Traceback (most recent call last):
  File "D:\(Project\Envs\MyDjango-UsDAF7iD\lib\site-packages\django\core\handlers\exception.py", line 34, in inner
    response = get_response(request)
  File "D:\(Project\Envs\MyDjango-UsDAF7iD\lib\site-packages\django\core\handlers\base.py", line 115, in _get_response
    response = self.process_exception_by_middleware(e, request)
  File "D:\(Project\Envs\MyDjango-UsDAF7iD\lib\site-packages\django\core\handlers\base.py", line 113, in _get_response
    response = wrapped_callback(request, *callback_args, **callback_kwargs)
  File "D:\(Project\Envs\MyDjango-UsDAF7iD\lib\site-packages\django\views\generic\base.py", line 71, in view
    return self.dispatch(request, *args, **kwargs)
  File "D:\(Project\Envs\MyDjango-UsDAF7iD\lib\site-packages\django\views\generic\base.py", line 97, in dispatch
    return handler(request, *args, **kwargs)
  File "D:\(Project\MyDjango\ltmall\apps\users\views.py", line 35, in post
    res = [i for i in info.values()]
AttributeError: 'list' object has no attribute 'values'
